正常来说遇到异常时，程序会报错退出。我们可以手动抛出一个异常。

## 抛出异常
```C++
throw(异常对象);//异常对象可以时内置类型(int,char)，也可以是自定义类型；
```

在对异常捕获后，程序在try内发生异常，将会跳转到catch语句对异常进行处理。并将异常作为对象发生给catch。

## 捕获异常
```C++
try{
	//正常代码;
}catch(异常对象){
	//处理异常的代码;
}
```

可以使用多个catch，异常抛出后匹配最近的同类型catch。
```C++
try{
	//正常代码;
}catch(const char* e)){
	//处理抛出char*类型异常的代码
}catch(cost string e){
	//处理抛出string类型异常的代码
}
```

一般来说，会专门定义一个类作为异常抛出和捕获的类型

```C++
class Exception{
private:
	int _errid; //错误码
	string _errmsg; //错误描述
};
```

捕获任意类型的异常
```C++
try{

}catch(...){
	cout << "未知异常" << endl;
}
```

> 子类异常可以被父类捕获
> 异常捕获可以嵌套多层，可以在捕获异常后，处理特化部分后再抛给最外层处理通用部分。

## 异常声明

C++98要求在函数声明时，声明会抛出什么类型的异常
```C++
void fun() throw(异常1，异常2);
```
> 如果throw内为空，则表明函数不抛异常

C++98的方案要求开发者明确能不能抛异常和能抛出什么异常，但是实际开发中，开发者不一定能给出准确的能抛出哪些异常

在C++11中，只要求开发者标识哪些函数不会抛异常

```C++
void fun() noexcept;
```


